<?xml version="1.0"?>
<!-- This URDF was automatically created by SolidWorks to URDF Exporter! Originally created by Stephen Brawner (brawner@gmail.com) 
     Commit Version: 1.6.0-4-g7f85cfe  Build Version: 1.6.7995.38578
     For more information, please see http://wiki.ros.org/sw_urdf_exporter -->
<robot
  name="myrobot" xmlns:xacro="http://ros.org/wiki/xacro">
  <link
    name="base_link">
    <inertial>
      <origin
        xyz="-6.927E-05 0.079176 -0.072666"
        rpy="0 0 0" />
      <mass
        value="31.145" />
      <inertia
        ixx="1.6476"
        ixy="8.2668E-17"
        ixz="9.0551E-18"
        iyy="0.4564"
        iyz="0.0087202"
        izz="1.9441" />
    </inertial>
    <visual>
      <origin
        xyz="0 0 0"
        rpy="0 0 0" />
      <geometry>
        <mesh
          filename="package://myrobot/meshes/base_link.STL" />
      </geometry>
      <material
        name="">
        <color
          rgba="0.9098 0.67843 0.13725 1" />
      </material>
    </visual>
    <collision>
      <origin
        xyz="0 0 0"
        rpy="0 0 0" />
      <geometry>
        <mesh
          filename="package://myrobot/meshes/base_link.STL" />
      </geometry>
    </collision>
  </link>
  <link
    name="sideplate1">
    <inertial>
      <origin
        xyz="0.0088125 -1.3878E-17 -0.012633"
        rpy="0 0 0" />
      <mass
        value="0.89948" />
      <inertia
        ixx="0.039805"
        ixy="-1.2469E-18"
        ixz="0.0002215"
        iyy="0.0024527"
        iyz="-6.7695E-19"
        izz="0.037736" />
    </inertial>
    <visual>
      <origin
        xyz="0 0 0"
        rpy="0 0 0" />
      <geometry>
        <mesh
          filename="package://myrobot/meshes/sideplate1.STL" />
      </geometry>
      <material
        name="">
        <color
          rgba="0.098039 0.098039 0.098039 1" />
      </material>
    </visual>
    <collision>
      <origin
        xyz="0 0 0"
        rpy="0 0 0" />
      <geometry>
        <mesh
          filename="package://myrobot/meshes/sideplate1.STL" />
      </geometry>
    </collision>
  </link>
  <joint
    name="sideplate1joint"
    type="fixed">
    <origin
      xyz="0.17993 0.077892 -0.057978"
      rpy="0 0 0" />
    <parent
      link="base_link" />
    <child
      link="sideplate1" />
    <axis
      xyz="0 0 0" />
  </joint>
  <link
    name="sideplate2">
    <inertial>
      <origin
        xyz="0.0088125 9.7145E-17 -0.012633"
        rpy="0 0 0" />
      <mass
        value="0.89948" />
      <inertia
        ixx="0.039805"
        ixy="-5.5208E-17"
        ixz="0.0002215"
        iyy="0.0024527"
        iyz="-7.4176E-18"
        izz="0.037736" />
    </inertial>
    <visual>
      <origin
        xyz="0 0 0"
        rpy="0 0 0" />
      <geometry>
        <mesh
          filename="package://myrobot/meshes/sideplate2.STL" />
      </geometry>
      <material
        name="">
        <color
          rgba="0.098039 0.098039 0.098039 1" />
      </material>
    </visual>
    <collision>
      <origin
        xyz="0 0 0"
        rpy="0 0 0" />
      <geometry>
        <mesh
          filename="package://myrobot/meshes/sideplate2.STL" />
      </geometry>
    </collision>
  </link>
  <joint
    name="sideplate2joint"
    type="fixed">
    <origin
      xyz="-0.18007 0.077892 -0.057978"
      rpy="0 0 3.1416" />
    <parent
      link="base_link" />
    <child
      link="sideplate2" />
    <axis
      xyz="0 0 0" />
  </joint>
  <link
    name="topplate">
    <inertial>
      <origin
        xyz="3.179E-09 0.08492 0.17673"
        rpy="0 0 0" />
      <mass
        value="7.95" />
      <inertia
        ixx="0.18114"
        ixy="-3.5783E-09"
        ixz="-1.6837E-09"
        iyy="0.12324"
        iyz="-0.035423"
        izz="0.22857" />
    </inertial>
    <visual>
      <origin
        xyz="0 0 0"
        rpy="0 0 0" />
      <geometry>
        <mesh
          filename="package://myrobot/meshes/topplate.STL" />
      </geometry>
      <material
        name="">
        <color
          rgba="0.098039 0.098039 0.098039 1" />
      </material>
    </visual>
    <collision>
      <origin
        xyz="0 0 0"
        rpy="0 0 0" />
      <geometry>
        <mesh
          filename="package://myrobot/meshes/topplate.STL" />
      </geometry>
    </collision>
  </link>
  <joint
    name="topplatejoint"
    type="fixed">
    <origin
      xyz="-6.927E-05 0.085392 -0.11798"
      rpy="0 0 0" />
    <parent
      link="base_link" />
    <child
      link="topplate" />
    <axis
      xyz="0 0 0" />
  </joint>
  <link
    name="bumper">
    <inertial>
      <origin
        xyz="2.32715696234555E-06 -0.0323325237986916 -1.71220126410354E-08"
        rpy="0 0 0" />
      <mass
        value="0.302492815875976" />
      <inertia
        ixx="7.75928896101748E-05"
        ixy="-5.93704251328147E-09"
        ixz="7.78542148406424E-09"
        iyy="0.00346052981980925"
        iyz="-1.38760420596571E-10"
        izz="0.00350713709313517" />
    </inertial>
    <visual>
      <origin
        xyz="0 0 0"
        rpy="0 0 0" />
      <geometry>
        <mesh
          filename="package://myrobot/meshes/bumper.STL" />
      </geometry>
      <material
        name="">
        <color
          rgba="0.0980392156862745 0.0980392156862745 0.0980392156862745 1" />
      </material>
    </visual>
    <collision>
      <origin
        xyz="0 0 0"
        rpy="0 0 0" />
      <geometry>
        <mesh
          filename="package://myrobot/meshes/bumper.STL" />
      </geometry>
    </collision>
  </link>
  <joint
    name="bumperjoint"
    type="fixed">
    <origin
      xyz="-6.927E-05 -0.28961 -0.087978"
      rpy="0 0 0" />
    <parent
      link="base_link" />
    <child
      link="bumper" />
    <axis
      xyz="0 0 0" />
  </joint>
  <link
    name="FLrim">
    <inertial>
      <origin
        xyz="0.038612 -7.6254E-07 8.7916E-08"
        rpy="0 0 0" />
      <mass
        value="0.070555" />
      <inertia
        ixx="0.00023745"
        ixy="-2.4572E-11"
        ixz="8.3423E-12"
        iyy="0.00014711"
        iyz="1.0844E-10"
        izz="0.00014711" />
    </inertial>
    <visual>
      <origin
        xyz="0 0 0"
        rpy="0 0 0" />
      <geometry>
        <mesh
          filename="package://myrobot/meshes/FLrim.STL" />
      </geometry>
      <material
        name="">
        <color
          rgba="0.9098 0.67843 0.13725 1" />
      </material>
    </visual>
    <collision>
      <origin
        xyz="0 0 0"
        rpy="0 0 0" />
      <geometry>
        <mesh
          filename="package://myrobot/meshes/FLrim.STL" />
      </geometry>
    </collision>
  </link>
  <joint
    name="FLrimjoint"
    type="continuous">
    <origin
      xyz="0.20105 -0.14211 -0.11298"
      rpy="2.5167 0 0" />
    <parent
      link="base_link" />
    <child
      link="FLrim" />
    <axis
      xyz="1 0 0" />
  </joint>
  <link
    name="FLtyre">
    <inertial>
      <origin
        xyz="0.680831966966673 1.52727570565947E-05 0.499097694121612"
        rpy="0 0 0" />
      <mass
        value="0.479673738200358" />
      <inertia
        ixx="0.00444535197676417"
        ixy="-5.04633815809319E-07"
        ixz="4.40704898132227E-07"
        iyy="0.00441497920172615"
        iyz="3.66559994233846E-06"
        izz="0.00804089627286017" />
    </inertial>
    <visual>
      <origin
        xyz="0 0 0"
        rpy="0 0 0" />
      <geometry>
        <mesh
          filename="package://myrobot/meshes/FLtyre.STL" />
      </geometry>
      <material
        name="">
        <color
          rgba="0.792156862745098 0.819607843137255 0.933333333333333 1" />
      </material>
    </visual>
    <collision>
      <origin
        xyz="0 0 0"
        rpy="0 0 0" />
      <geometry>
        <mesh
          filename="package://myrobot/meshes/FLtyre.STL" />
      </geometry>
    </collision>
  </link>
  <joint
    name="FLtyrejoint"
    type="fixed">
    <origin
      xyz="0.53616 -0.65541 -0.18438"
      rpy="-1.5708 -0.27424 1.5708" />
    <parent
      link="FLrim" />
    <child
      link="FLtyre" />
    <axis
      xyz="0 0 0" />
  </joint>
  <link
    name="BLrim">
    <inertial>
      <origin
        xyz="0.038612 -7.5745E-07 9.4907E-08"
        rpy="0 0 0" />
      <mass
        value="0.070555" />
      <inertia
        ixx="0.00023745"
        ixy="-2.2007E-11"
        ixz="8.8569E-12"
        iyy="0.00014711"
        iyz="9.22E-11"
        izz="0.00014711" />
    </inertial>
    <visual>
      <origin
        xyz="0 0 0"
        rpy="0 0 0" />
      <geometry>
        <mesh
          filename="package://myrobot/meshes/BLrim.STL" />
      </geometry>
      <material
        name="">
        <color
          rgba="0.9098 0.67843 0.13725 1" />
      </material>
    </visual>
    <collision>
      <origin
        xyz="0 0 0"
        rpy="0 0 0" />
      <geometry>
        <mesh
          filename="package://myrobot/meshes/BLrim.STL" />
      </geometry>
    </collision>
  </link>
  <joint
    name="BLrimjoint"
    type="continuous">
    <origin
      xyz="0.20105 0.29789 -0.11298"
      rpy="0.44139 0 0" />
    <parent
      link="base_link" />
    <child
      link="BLrim" />
    <axis
      xyz="1 0 0" />
  </joint>
  <link
    name="BLtyre">
    <inertial>
      <origin
        xyz="-2.4242E-05 1.5185E-05 -0.036514"
        rpy="0 0 0" />
      <mass
        value="0.47967" />
      <inertia
        ixx="0.0044454"
        ixy="-5.0462E-07"
        ixz="4.4215E-07"
        iyy="0.004415"
        iyz="3.6655E-06"
        izz="0.0080409" />
    </inertial>
    <visual>
      <origin
        xyz="0 0 0"
        rpy="0 0 0" />
      <geometry>
        <mesh
          filename="package://myrobot/meshes/BLtyre.STL" />
      </geometry>
      <material
        name="">
        <color
          rgba="0.79216 0.81961 0.93333 1" />
      </material>
    </visual>
    <collision>
      <origin
        xyz="0 0 0"
        rpy="0 0 0" />
      <geometry>
        <mesh
          filename="package://myrobot/meshes/BLtyre.STL" />
      </geometry>
    </collision>
  </link>
  <joint
    name="BLtyrejoint"
    type="fixed">
    <origin
      xyz="0 0 0"
      rpy="-1.5708 -1.1297 1.5708" />
    <parent
      link="BLrim" />
    <child
      link="BLtyre" />
    <axis
      xyz="0 0 0" />
  </joint>
  <link
    name="FRrim">
    <inertial>
      <origin
        xyz="0.0386121574476349 -7.71932905013761E-07 8.89219001765085E-08"
        rpy="0 0 0" />
      <mass
        value="0.0705551501598538" />
      <inertia
        ixx="0.000237450317802295"
        ixy="-2.41933944000634E-11"
        ixz="7.7554066912048E-12"
        iyy="0.000147110461073436"
        iyz="1.02103034062704E-10"
        izz="0.000147109811006801" />
    </inertial>
    <visual>
      <origin
        xyz="0 0 0"
        rpy="0 0 0" />
      <geometry>
        <mesh
          filename="package://myrobot/meshes/FRrim.STL" />
      </geometry>
      <material
        name="">
        <color
          rgba="0.909803921568627 0.67843137254902 0.137254901960784 1" />
      </material>
    </visual>
    <collision>
      <origin
        xyz="0 0 0"
        rpy="0 0 0" />
      <geometry>
        <mesh
          filename="package://myrobot/meshes/FRrim.STL" />
      </geometry>
    </collision>
  </link>
  <joint
    name="FRrimjoint"
    type="continuous">
    <origin
      xyz="-0.20119 -0.14211 -0.11298"
      rpy="0 0 3.1416" />
    <parent
      link="base_link" />
    <child
      link="FRrim" />
    <axis
      xyz="-1 0 0" />
  </joint>
  <link
    name="FRtyre">
    <inertial>
      <origin
        xyz="-2.4397E-05 1.5418E-05 -0.036925"
        rpy="0 0 0" />
      <mass
        value="0.47967" />
      <inertia
        ixx="0.0044453"
        ixy="-5.0751E-07"
        ixz="4.4173E-07"
        iyy="0.004415"
        iyz="3.6636E-06"
        izz="0.0080409" />
    </inertial>
    <visual>
      <origin
        xyz="0 0 0"
        rpy="0 0 0" />
      <geometry>
        <mesh
          filename="package://myrobot/meshes/FRtyre.STL" />
      </geometry>
      <material
        name="">
        <color
          rgba="0.79216 0.81961 0.93333 1" />
      </material>
    </visual>
    <collision>
      <origin
        xyz="0 0 0"
        rpy="0 0 0" />
      <geometry>
        <mesh
          filename="package://myrobot/meshes/FRtyre.STL" />
      </geometry>
    </collision>
  </link>
  <joint
    name="FRtyrejoint"
    type="fixed">
    <origin
      xyz="0 0 0"
      rpy="1.5708 -1.388 -1.5708" />
    <parent
      link="FRrim" />
    <child
      link="FRtyre" />
    <axis
      xyz="0 0 0" />
  </joint>
  <link
    name="BRrim">
    <inertial>
      <origin
        xyz="0.038612161553638 -7.57250231159246E-07 9.42717224838852E-08"
        rpy="0 0 0" />
      <mass
        value="0.0705551858750099" />
      <inertia
        ixx="0.000237450354698889"
        ixy="-2.19496095242471E-11"
        ixz="8.68876160602055E-12"
        iyy="0.000147110466830396"
        iyz="9.19582824770754E-11"
        izz="0.000147109842257438" />
    </inertial>
    <visual>
      <origin
        xyz="0 0 0"
        rpy="0 0 0" />
      <geometry>
        <mesh
          filename="package://myrobot/meshes/BRrim.STL" />
      </geometry>
      <material
        name="">
        <color
          rgba="0.909803921568627 0.67843137254902 0.137254901960784 1" />
      </material>
    </visual>
    <collision>
      <origin
        xyz="0 0 0"
        rpy="0 0 0" />
      <geometry>
        <mesh
          filename="package://myrobot/meshes/BRrim.STL" />
      </geometry>
    </collision>
  </link>
  <joint
    name="BRrimjoint"
    type="continuous">
    <origin
      xyz="-0.20119 0.29789 -0.11298"
      rpy="-1.3187 0 3.1416" />
    <parent
      link="base_link" />
    <child
      link="BRrim" />
    <axis
      xyz="-1 0 0" />
  </joint>
  <link
    name="BRtyre">
    <inertial>
      <origin
        xyz="-2.426E-05 1.5202E-05 -0.03685"
        rpy="0 0 0" />
      <mass
        value="0.47967" />
      <inertia
        ixx="0.0044454"
        ixy="-5.0523E-07"
        ixz="4.426E-07"
        iyy="0.004415"
        iyz="3.6652E-06"
        izz="0.0080409" />
    </inertial>
    <visual>
      <origin
        xyz="0 0 0"
        rpy="0 0 0" />
      <geometry>
        <mesh
          filename="package://myrobot/meshes/BRtyre.STL" />
      </geometry>
      <material
        name="">
        <color
          rgba="0.79216 0.81961 0.93333 1" />
      </material>
    </visual>
    <collision>
      <origin
        xyz="0 0 0"
        rpy="0 0 0" />
      <geometry>
        <mesh
          filename="package://myrobot/meshes/BRtyre.STL" />
      </geometry>
    </collision>
  </link>
  <joint
    name="BRtyrejoint"
    type="fixed">
    <origin
      xyz="0 0 0"
      rpy="1.5708 -0.27335 -1.5708" />
    <parent
      link="BRrim" />
    <child
      link="BRtyre" />
    <axis
      xyz="0 0 0" />
  </joint>

<xacro:macro name="yellow_color">
    <visual>
        <material>
            <ambient>0.0 0.0 0.0 1</ambient>
            <diffuse>1.0 0.66 0.1137 1</diffuse> <!-- Adjusted for yellow color -->
            <specular>0.0 0.0 0.0 0</specular>
            <emissive>0 0 0 0</emissive>
        </material>
    </visual>
</xacro:macro>

<gazebo reference="base_link">
    <xacro:yellow_color />
</gazebo>

  <gazebo reference="BRrim">
    <xacro:yellow_color />
  </gazebo>
  
  <gazebo reference="BLrim">
    <xacro:yellow_color />
  </gazebo>

  <gazebo reference="FRrim">
    <xacro:yellow_color />
  </gazebo>

    <gazebo reference="FLrim">
    <xacro:yellow_color />
  </gazebo>
  
  <gazebo reference="sideplate1">
    <material>Gazebo/DarkGrey</material>
  </gazebo>

  <gazebo reference="sideplate2">
    <material>Gazebo/DarkGrey</material>
  </gazebo>

    <gazebo reference="topplate">
    <material>Gazebo/DarkGrey</material>
  </gazebo>

    <gazebo reference="bumper">
    <material>Gazebo/DarkGrey</material>
  </gazebo>

  <gazebo reference="BRtyre">
    <material>Gazebo/DarkGrey</material>
  </gazebo>


  <gazebo reference="BLtyre">
    <material>Gazebo/DarkGrey</material>
  </gazebo>

  <gazebo reference="FRtyre">
    <material>Gazebo/DarkGrey</material>
  </gazebo>

  <gazebo reference="FLtyre">
    <material>Gazebo/DarkGrey</material>
  </gazebo>




<gazebo>
  <plugin filename="libgazebo_ros2_control.so" name="gazebo_ros2_control">
  <parameters>$(find myrobot)/config/control.yaml</parameters>
  </plugin>
</gazebo>


<ros2_control name="GazeboSystem" type="system">

<hardware>
<plugin>gazebo_ros2_control/GazeboSystem</plugin>
</hardware> 


# Velocity Controllers

<joint name="BRrimjoint">
<command_interface name="velocity">
<param name="min">-1000.0</param>
<param name="max">1000.0</param>
</command_interface>
<state_interface name="position"/>
<state_interface name="velocity"/>
</joint>


<joint name="BLrimjoint">
<command_interface name="velocity">
<param name="min">-1000.0</param>
<param name="max">1000.0</param>
</command_interface>
<state_interface name="position"/>
<state_interface name="velocity"/>
</joint>

<joint name="FRrimjoint">
<command_interface name="velocity">
<param name="min">-1000.0</param>
<param name="max">1000.0</param>
</command_interface>
<state_interface name="position"/>
<state_interface name="velocity"/>
</joint>

<joint name="FLrimjoint">
<command_interface name="velocity">
<param name="min">-1000.0</param>
<param name="max">1000.0</param>
</command_interface>
<state_interface name="position"/>
<state_interface name="velocity"/>
</joint>
</ros2_control>




# ------------------Camera, IMU, LIDAR plugins------------------------

  <link name="camera_link">
    <collision>
      <origin xyz="0 0 0" rpy="0 -1.57 3.14"/>
      <geometry>
        <mesh
          filename="package://myrobot/meshes/realsense.dae" />
      </geometry>
    </collision>

    <visual>
      <origin xyz="0 0 0" rpy="0 -1.57 3.14"/>
      <geometry>
        <mesh
          filename="package://myrobot/meshes/realsense.dae" />
      </geometry>
      <!-- <material>Gazebo/Red</material> -->
    </visual>

    <inertial>
      <mass value="1e-5" />
      <origin xyz="0 0 0" rpy="0 -1.57 3.14"/>
      <inertia ixx="1e-6" ixy="0" ixz="0" iyy="1e-6" iyz="0" izz="1e-6" />
    </inertial>
  </link>

  <joint name="camera_joint" type="fixed">
    <axis xyz="0 1 0" />
    <origin xyz="-0.02 -0.2 0.043" rpy="0 0 -1.57"/>
    <parent link="base_link"/>
    <child link="camera_link"/>
  </joint>

<gazebo reference="camera_link">
    <sensor type="camera" name="camera1">
      <update_rate>30.0</update_rate>
      <camera name="head">
        <horizontal_fov>1.3962634</horizontal_fov>
        <image>
          <width>1200</width>
          <height>600</height>
          <format>R8G8B8</format>
        </image>
        <clip>
          <near>0.02</near>
          <far>300</far>
        </clip>
        <noise>
          <type>gaussian</type>
          <!-- Noise is sampled independently per pixel on each frame.
               That pixel's noise value is added to each of its color
               channels, which at that point lie in the range [0,1]. -->
          <mean>0.0</mean>
          <stddev>0.007</stddev>
        </noise>
      </camera>
      <plugin name="camera_controller" filename="libgazebo_ros_camera.so">
        <alwaysOn>true</alwaysOn>
        <updateRate>0.0</updateRate>
        <cameraName>camera1</cameraName>
        <imageTopicName>image_raw</imageTopicName>
        <cameraInfoTopicName>camera_info</cameraInfoTopicName>
        <frameName>camera_link</frameName>
        <hackBaseline>0.07</hackBaseline>
        <distortionK1>0.0</distortionK1>
        <distortionK2>0.0</distortionK2>
        <distortionK3>0.0</distortionK3>
        <distortionT1>0.0</distortionT1>
        <distortionT2>0.0</distortionT2>
      </plugin>
    </sensor>
  </gazebo>


  <!-- Define LiDAR link -->
  <link name="lidar_link">
    <visual>
      <origin xyz="0.0 0 0.073" rpy="0 0 0"/>
      <geometry>
        <mesh
          filename="package://myrobot/meshes/lidar.dae" />
      </geometry>
    </visual>
    <collision>
      <origin xyz="0.0 0 0.073" rpy="0 0 0"/>
      <geometry>
        <mesh
          filename="package://myrobot/meshes/lidar.dae" />      
      </geometry>
    </collision>
    <inertial>
      <origin xyz="0.0 0 0.073" rpy="0 0 0"/>
      <mass value="1"/>
      <inertia ixx="0.1" ixy="0" ixz="0" iyy="0.1" iyz="0" izz="0.1"/>
    </inertial>
  </link>

  <!-- Define joint connecting base link and LiDAR link -->
  <joint name="lidar_joint" type="fixed">
    <origin xyz="0 0 0" rpy="0 0 0"/>
    <parent link="base_link"/>
    <child link="lidar_link"/>
  </joint>

  

<gazebo reference="lidar_link">
  <sensor name="lidar" type="ray">
    <pose>0.0 0.0 0.08 0 0 3.14</pose>
    <always_on>true</always_on>
    <visualize>true</visualize>
    <update_rate>5</update_rate>
    <ray>
      <scan>
        <horizontal>
          <samples>21</samples>
          <resolution>1.0</resolution>
          <min_angle>0.0</min_angle>
          <max_angle>3.14</max_angle>
        </horizontal>
      </scan>
      <range>
        <min>0.10000</min>
        <max>3</max>
        <resolution>0.015000</resolution>
      </range>
      <noise>
        <type>gaussian</type>
        <mean>0.0</mean>
        <stddev>0.01</stddev>
      </noise>
    </ray>
    <plugin name="scan" filename="libgazebo_ros_ray_sensor.so">
      <ros>
        <remapping>~/out:=scan</remapping>
      </ros>
      <output_type>sensor_msgs/LaserScan</output_type>
      <frame_name>lidar_link</frame_name>
    </plugin>
  </sensor>
  </gazebo>





<link name="imu_link">
    <visual>
       <geometry>
       <cylinder length="0.06" radius="0.02"/>
      </geometry>
    <!-- <material>Gazebo/Red</material> -->
    </visual>
  </link>

<joint name="imujoint" type="fixed">
    <origin
      xyz="-0.0 -0.0 -0.1"
      rpy="0 0 0" />    
    <parent
      link="base_link" />
    <child
      link="imu_link" />
</joint>

  <gazebo reference="imu_link">
    <material>Gazebo/Red</material>
  </gazebo>

<gazebo reference="imu_link">
  <gravity>true</gravity>
  <sensor name="imu_sensor" type="imu">
    <always_on>true</always_on>
    <update_rate>100</update_rate>
    <visualize>true</visualize>
    <topic>__default_topic__</topic>
    <plugin filename="libgazebo_ros_imu_sensor.so" name="imu_plugin">
      <topicName>imu</topicName>
      <bodyName>imu_link</bodyName>
      <updateRateHZ>10.0</updateRateHZ>
      <gaussianNoise>0.0</gaussianNoise>
      <xyzOffset>0 0 0</xyzOffset>
      <rpyOffset>0 0 0</rpyOffset>
      <frameName>imu_link</frameName>
      <initialOrientationAsReference>false</initialOrientationAsReference>
    </plugin>
    <pose>0 0 0 0 0 0</pose>
  </sensor>
</gazebo>

</robot>